Traceback (most recent call last):
  File "/home/jovyan/.conda/envs/aipbase/lib/python3.10/site-packages/urllib3/connectionpool.py", line 716, in urlopen
    httplib_response = self._make_request(
  File "/home/jovyan/.conda/envs/aipbase/lib/python3.10/site-packages/urllib3/connectionpool.py", line 404, in _make_request
    self._validate_conn(conn)
  File "/home/jovyan/.conda/envs/aipbase/lib/python3.10/site-packages/urllib3/connectionpool.py", line 1061, in _validate_conn
    conn.connect()
  File "/home/jovyan/.conda/envs/aipbase/lib/python3.10/site-packages/urllib3/connection.py", line 419, in connect
    self.sock = ssl_wrap_socket(
  File "/home/jovyan/.conda/envs/aipbase/lib/python3.10/site-packages/urllib3/util/ssl_.py", line 458, in ssl_wrap_socket
    ssl_sock = _ssl_wrap_socket_impl(
  File "/home/jovyan/.conda/envs/aipbase/lib/python3.10/site-packages/urllib3/util/ssl_.py", line 502, in _ssl_wrap_socket_impl
    return ssl_context.wrap_socket(sock, server_hostname=server_hostname)
  File "/home/jovyan/.conda/envs/aipbase/lib/python3.10/ssl.py", line 513, in wrap_socket
    return self.sslsocket_class._create(
  File "/home/jovyan/.conda/envs/aipbase/lib/python3.10/ssl.py", line 1104, in _create
    self.do_handshake()
  File "/home/jovyan/.conda/envs/aipbase/lib/python3.10/ssl.py", line 1375, in do_handshake
    self._sslobj.do_handshake()
ConnectionResetError: [Errno 104] Connection reset by peer

During handling of the above exception, another exception occurred:

Traceback (most recent call last):
  File "/home/jovyan/.conda/envs/aipbase/lib/python3.10/site-packages/requests/adapters.py", line 489, in send
    resp = conn.urlopen(
  File "/home/jovyan/.conda/envs/aipbase/lib/python3.10/site-packages/urllib3/connectionpool.py", line 802, in urlopen
    retries = retries.increment(
  File "/home/jovyan/.conda/envs/aipbase/lib/python3.10/site-packages/urllib3/util/retry.py", line 552, in increment
    raise six.reraise(type(error), error, _stacktrace)
  File "/home/jovyan/.conda/envs/aipbase/lib/python3.10/site-packages/urllib3/packages/six.py", line 769, in reraise
    raise value.with_traceback(tb)
  File "/home/jovyan/.conda/envs/aipbase/lib/python3.10/site-packages/urllib3/connectionpool.py", line 716, in urlopen
    httplib_response = self._make_request(
  File "/home/jovyan/.conda/envs/aipbase/lib/python3.10/site-packages/urllib3/connectionpool.py", line 404, in _make_request
    self._validate_conn(conn)
  File "/home/jovyan/.conda/envs/aipbase/lib/python3.10/site-packages/urllib3/connectionpool.py", line 1061, in _validate_conn
    conn.connect()
  File "/home/jovyan/.conda/envs/aipbase/lib/python3.10/site-packages/urllib3/connection.py", line 419, in connect
    self.sock = ssl_wrap_socket(
  File "/home/jovyan/.conda/envs/aipbase/lib/python3.10/site-packages/urllib3/util/ssl_.py", line 458, in ssl_wrap_socket
    ssl_sock = _ssl_wrap_socket_impl(
  File "/home/jovyan/.conda/envs/aipbase/lib/python3.10/site-packages/urllib3/util/ssl_.py", line 502, in _ssl_wrap_socket_impl
    return ssl_context.wrap_socket(sock, server_hostname=server_hostname)
  File "/home/jovyan/.conda/envs/aipbase/lib/python3.10/ssl.py", line 513, in wrap_socket
    return self.sslsocket_class._create(
  File "/home/jovyan/.conda/envs/aipbase/lib/python3.10/ssl.py", line 1104, in _create
    self.do_handshake()
  File "/home/jovyan/.conda/envs/aipbase/lib/python3.10/ssl.py", line 1375, in do_handshake
    self._sslobj.do_handshake()
urllib3.exceptions.ProtocolError: ('Connection aborted.', ConnectionResetError(104, 'Connection reset by peer'))

During handling of the above exception, another exception occurred:

Traceback (most recent call last):
  File "/home/jovyan/jonglae/Retry1/YOLO/Custom_OBB_YOLO.py", line 145, in <module>
    # 메인 실행
  File "/home/jovyan/jonglae/Retry1/YOLO/Custom_OBB_YOLO.py", line 130, in main
  File "/home/jovyan/jonglae/Retry1/YOLO/Custom_OBB_YOLO.py", line 49, in second_stage_training
    # 두 번째 단계 (첫 번째 학습 결과를 이용해 추가 학습 진행)
  File "/home/jovyan/jonglae/Retry1/YOLO/Custom_OBB_YOLO.py", line 9, in __init__
    class CustomYOLO(YOLO):
  File "/home/jovyan/.conda/envs/aipbase/lib/python3.10/site-packages/ultralytics/models/yolo/model.py", line 23, in __init__
    super().__init__(model=model, task=task, verbose=verbose)
  File "/home/jovyan/.conda/envs/aipbase/lib/python3.10/site-packages/ultralytics/engine/model.py", line 145, in __init__
    self._load(model, task=task)
  File "/home/jovyan/.conda/envs/aipbase/lib/python3.10/site-packages/ultralytics/engine/model.py", line 285, in _load
    self.model, self.ckpt = attempt_load_one_weight(weights)
  File "/home/jovyan/.conda/envs/aipbase/lib/python3.10/site-packages/ultralytics/nn/tasks.py", line 909, in attempt_load_one_weight
    ckpt, weight = torch_safe_load(weight)  # load ckpt
  File "/home/jovyan/.conda/envs/aipbase/lib/python3.10/site-packages/ultralytics/nn/tasks.py", line 814, in torch_safe_load
    file = attempt_download_asset(weight)  # search online if missing locally
  File "/home/jovyan/.conda/envs/aipbase/lib/python3.10/site-packages/ultralytics/utils/downloads.py", line 457, in attempt_download_asset
    tag, assets = get_github_assets(repo, release)
  File "/home/jovyan/.conda/envs/aipbase/lib/python3.10/site-packages/ultralytics/utils/downloads.py", line 402, in get_github_assets
    r = requests.get(url)  # github api
  File "/home/jovyan/.conda/envs/aipbase/lib/python3.10/site-packages/requests/api.py", line 73, in get
    return request("get", url, params=params, **kwargs)
  File "/home/jovyan/.conda/envs/aipbase/lib/python3.10/site-packages/requests/api.py", line 59, in request
    return session.request(method=method, url=url, **kwargs)
  File "/home/jovyan/.conda/envs/aipbase/lib/python3.10/site-packages/requests/sessions.py", line 587, in request
    resp = self.send(prep, **send_kwargs)
  File "/home/jovyan/.conda/envs/aipbase/lib/python3.10/site-packages/requests/sessions.py", line 701, in send
    r = adapter.send(request, **kwargs)
  File "/home/jovyan/.conda/envs/aipbase/lib/python3.10/site-packages/requests/adapters.py", line 547, in send
    raise ConnectionError(err, request=request)
requests.exceptions.ConnectionError: ('Connection aborted.', ConnectionResetError(104, 'Connection reset by peer'))
