Traceback (most recent call last):
  File "/home/jovyan/.conda/envs/aipbase/lib/python3.10/site-packages/ultralytics/engine/trainer.py", line 559, in get_dataset
    data = check_det_dataset(self.args.data)
  File "/home/jovyan/.conda/envs/aipbase/lib/python3.10/site-packages/ultralytics/data/utils.py", line 268, in check_det_dataset
    file = check_file(dataset)
  File "/home/jovyan/.conda/envs/aipbase/lib/python3.10/site-packages/ultralytics/utils/checks.py", line 517, in check_file
    raise FileNotFoundError(f"'{file}' does not exist")
FileNotFoundError: 'runs/DOTAv1-ms.yaml' does not exist

The above exception was the direct cause of the following exception:

Traceback (most recent call last):
  File "/home/jovyan/jonglae/Retry1/YOLO/checkyolo4.py", line 63, in <module>
    train_with_accumulation(model, train_data, epochs=1, batch_size=batch_size, accumulation_steps=accumulation_steps, image_size=image_size)
  File "/home/jovyan/jonglae/Retry1/YOLO/checkyolo4.py", line 31, in train_with_accumulation
    model.train()
  File "/home/jovyan/.conda/envs/aipbase/lib/python3.10/site-packages/ultralytics/engine/model.py", line 796, in train
    self.trainer = (trainer or self._smart_load("trainer"))(overrides=args, _callbacks=self.callbacks)
  File "/home/jovyan/.conda/envs/aipbase/lib/python3.10/site-packages/ultralytics/models/yolo/obb/train.py", line 29, in __init__
    super().__init__(cfg, overrides, _callbacks)
  File "/home/jovyan/.conda/envs/aipbase/lib/python3.10/site-packages/ultralytics/engine/trainer.py", line 133, in __init__
    self.trainset, self.testset = self.get_dataset()
  File "/home/jovyan/.conda/envs/aipbase/lib/python3.10/site-packages/ultralytics/engine/trainer.py", line 563, in get_dataset
    raise RuntimeError(emojis(f"Dataset '{clean_url(self.args.data)}' error ❌ {e}")) from e
RuntimeError: Dataset 'runs/DOTAv1-ms.yaml' error ❌ 'runs/DOTAv1-ms.yaml' does not exist
