Transferred 643/649 items from pretrained weights
TensorBoard: Start with 'tensorboard --logdir runs/detect/train5', view at http://localhost:6006/
Freezing layer 'model.23.dfl.conv.weight'
AMP: running Automatic Mixed Precision (AMP) checks with YOLO11n...
Downloading https://github.com/ultralytics/assets/releases/download/v8.3.0/yolo11n.pt to 'yolo11n.pt'...
⚠️ Download failure, retrying 1/3 https://github.com/ultralytics/assets/releases/download/v8.3.0/yolo11n.pt...
curl: (35) OpenSSL SSL_connect: Connection reset by peer in connection to github.com:443                                                                                                                

⚠️ Download failure, retrying 2/3 https://github.com/ultralytics/assets/releases/download/v8.3.0/yolo11n.pt...
curl: (35) OpenSSL SSL_connect: Connection reset by peer in connection to github.com:443                                                                                                                

⚠️ Download failure, retrying 3/3 https://github.com/ultralytics/assets/releases/download/v8.3.0/yolo11n.pt...
curl: (35) OpenSSL SSL_connect: Connection reset by peer in connection to github.com:443                                                                                                                

AMP: checks skipped ⚠️, offline and unable to download YOLO11n. Setting 'amp=True'. If you experience zero-mAP or NaN losses you can disable AMP with amp=False.
train: Scanning /home/jovyan/Y_T_Data/augmented_images.cache... 0 images, 25992 backgrounds, 0 corrupt: 100%|██████████| 25992/25992 [00:00<?, ?it/s]
WARNING ⚠️ No labels found in /home/jovyan/Y_T_Data/augmented_images.cache, training may not work correctly. See https://docs.ultralytics.com/datasets for dataset formatting guidance.
/home/jovyan/.conda/envs/aipbase/lib/python3.10/site-packages/albumentations/check_version.py:49: UserWarning: Error fetching version info <urlopen error _ssl.c:990: The handshake operation timed out>
  data = fetch_version_info()
albumentations: Blur(p=0.01, blur_limit=(3, 7)), MedianBlur(p=0.01, blur_limit=(3, 7)), ToGray(p=0.01, num_output_channels=3, method='weighted_average'), CLAHE(p=0.01, clip_limit=(1, 4.0), tile_grid_size=(8, 8))
Traceback (most recent call last):
  File "/home/jovyan/.conda/envs/aipbase/lib/python3.10/site-packages/ultralytics/data/base.py", line 125, in get_img_files
    assert im_files, f"{self.prefix}No images found in {img_path}. {FORMATS_HELP_MSG}"
AssertionError: val: No images found in /home/jovyan/Y_T_Data/val. Supported formats are:
images: {'dng', 'png', 'tif', 'jpeg', 'mpo', 'webp', 'jpg', 'pfm', 'bmp', 'tiff'}
videos: {'ts', 'gif', 'webm', 'wmv', 'asf', 'avi', 'mov', 'mpeg', 'm4v', 'mp4', 'mkv', 'mpg'}

The above exception was the direct cause of the following exception:

Traceback (most recent call last):
  File "/home/jovyan/jonglae/Retry1/2. B-BOX/base_yolo_detection.py", line 16, in <module>
    model.train(data=train_data, epochs=50, imgsz=640, batch=16, lr0=0.001, device='cuda')
  File "/home/jovyan/.conda/envs/aipbase/lib/python3.10/site-packages/ultralytics/engine/model.py", line 802, in train
    self.trainer.train()
  File "/home/jovyan/.conda/envs/aipbase/lib/python3.10/site-packages/ultralytics/engine/trainer.py", line 207, in train
    self._do_train(world_size)
  File "/home/jovyan/.conda/envs/aipbase/lib/python3.10/site-packages/ultralytics/engine/trainer.py", line 327, in _do_train
    self._setup_train(world_size)
  File "/home/jovyan/.conda/envs/aipbase/lib/python3.10/site-packages/ultralytics/engine/trainer.py", line 294, in _setup_train
    self.test_loader = self.get_dataloader(
  File "/home/jovyan/.conda/envs/aipbase/lib/python3.10/site-packages/ultralytics/models/yolo/detect/train.py", line 49, in get_dataloader
    dataset = self.build_dataset(dataset_path, mode, batch_size)
  File "/home/jovyan/.conda/envs/aipbase/lib/python3.10/site-packages/ultralytics/models/yolo/detect/train.py", line 43, in build_dataset
    return build_yolo_dataset(self.args, img_path, batch, self.data, mode=mode, rect=mode == "val", stride=gs)
  File "/home/jovyan/.conda/envs/aipbase/lib/python3.10/site-packages/ultralytics/data/build.py", line 87, in build_yolo_dataset
    return dataset(
  File "/home/jovyan/.conda/envs/aipbase/lib/python3.10/site-packages/ultralytics/data/dataset.py", line 65, in __init__
    super().__init__(*args, **kwargs)
  File "/home/jovyan/.conda/envs/aipbase/lib/python3.10/site-packages/ultralytics/data/base.py", line 73, in __init__
    self.im_files = self.get_img_files(self.img_path)
  File "/home/jovyan/.conda/envs/aipbase/lib/python3.10/site-packages/ultralytics/data/base.py", line 127, in get_img_files
    raise FileNotFoundError(f"{self.prefix}Error loading data from {img_path}\n{HELP_URL}") from e
FileNotFoundError: val: Error loading data from /home/jovyan/Y_T_Data/val
See https://docs.ultralytics.com/datasets for dataset formatting guidance.
