Traceback (most recent call last):
  File "/home/jovyan/.conda/envs/aipbase/lib/python3.10/site-packages/ultralytics/engine/trainer.py", line 559, in get_dataset
    data = check_det_dataset(self.args.data)
  File "/home/jovyan/.conda/envs/aipbase/lib/python3.10/site-packages/ultralytics/data/utils.py", line 328, in check_det_dataset
    raise FileNotFoundError(m)
FileNotFoundError: 
Dataset '/home/jovyan/Y_T_Data/Y_T_Dataset_NEW.yaml' images not found ⚠️, missing path '/home/jovyan/Y_T_Data/val/image'
Note dataset download directory is '/home/jovyan/datasets'. You can update this in '/home/jovyan/.config/Ultralytics/settings.json'

The above exception was the direct cause of the following exception:

Traceback (most recent call last):
  File "/home/jovyan/jonglae/Retry1/2. B-BOX/base_yolo_renew.py", line 89, in <module>
    model.train(data=train_data, epochs=1, imgsz=640, batch=16, lr0=0.001, optimizer='SGD')
  File "/home/jovyan/.conda/envs/aipbase/lib/python3.10/site-packages/ultralytics/engine/model.py", line 796, in train
    self.trainer = (trainer or self._smart_load("trainer"))(overrides=args, _callbacks=self.callbacks)
  File "/home/jovyan/.conda/envs/aipbase/lib/python3.10/site-packages/ultralytics/engine/trainer.py", line 133, in __init__
    self.trainset, self.testset = self.get_dataset()
  File "/home/jovyan/.conda/envs/aipbase/lib/python3.10/site-packages/ultralytics/engine/trainer.py", line 563, in get_dataset
    raise RuntimeError(emojis(f"Dataset '{clean_url(self.args.data)}' error ❌ {e}")) from e
RuntimeError: Dataset '/home/jovyan/Y_T_Data/Y_T_Dataset_NEW.yaml' error ❌ 
Dataset '/home/jovyan/Y_T_Data/Y_T_Dataset_NEW.yaml' images not found ⚠️, missing path '/home/jovyan/Y_T_Data/val/image'
Note dataset download directory is '/home/jovyan/datasets'. You can update this in '/home/jovyan/.config/Ultralytics/settings.json'
