New cache created: /home/jovyan/data-vol-1/2nd/dataset/train/labels.cache
WARNING ⚠️ No images found in /home/jovyan/data-vol-1/2nd/dataset/train/labels.cache, training may not work correctly. See https://docs.ultralytics.com/datasets for dataset formatting guidance.
Traceback (most recent call last):
  File "/home/jovyan/jonglae/Retry1/2. B-BOX/1-1_obb_YOLO_11m.py", line 16, in <module>
    model.train(data=train_data, epochs=1, imgsz=640, batch=16, lr0=0.001, device='cuda', amp=False, patience=20, val=False)
  File "/home/jovyan/.conda/envs/aipbase/lib/python3.10/site-packages/ultralytics/engine/model.py", line 802, in train
    self.trainer.train()
  File "/home/jovyan/.conda/envs/aipbase/lib/python3.10/site-packages/ultralytics/engine/trainer.py", line 207, in train
    self._do_train(world_size)
  File "/home/jovyan/.conda/envs/aipbase/lib/python3.10/site-packages/ultralytics/engine/trainer.py", line 327, in _do_train
    self._setup_train(world_size)
  File "/home/jovyan/.conda/envs/aipbase/lib/python3.10/site-packages/ultralytics/engine/trainer.py", line 291, in _setup_train
    self.train_loader = self.get_dataloader(self.trainset, batch_size=batch_size, rank=LOCAL_RANK, mode="train")
  File "/home/jovyan/.conda/envs/aipbase/lib/python3.10/site-packages/ultralytics/models/yolo/detect/train.py", line 49, in get_dataloader
    dataset = self.build_dataset(dataset_path, mode, batch_size)
  File "/home/jovyan/.conda/envs/aipbase/lib/python3.10/site-packages/ultralytics/models/yolo/detect/train.py", line 43, in build_dataset
    return build_yolo_dataset(self.args, img_path, batch, self.data, mode=mode, rect=mode == "val", stride=gs)
  File "/home/jovyan/.conda/envs/aipbase/lib/python3.10/site-packages/ultralytics/data/build.py", line 87, in build_yolo_dataset
    return dataset(
  File "/home/jovyan/.conda/envs/aipbase/lib/python3.10/site-packages/ultralytics/data/dataset.py", line 65, in __init__
    super().__init__(*args, **kwargs)
  File "/home/jovyan/.conda/envs/aipbase/lib/python3.10/site-packages/ultralytics/data/base.py", line 74, in __init__
    self.labels = self.get_labels()
  File "/home/jovyan/.conda/envs/aipbase/lib/python3.10/site-packages/ultralytics/data/dataset.py", line 164, in get_labels
    len_cls, len_boxes, len_segments = (sum(x) for x in zip(*lengths))
ValueError: not enough values to unpack (expected 3, got 0)
