Traceback (most recent call last):
  File "/home/jovyan/jonglae/Retry1/DO/4_WB_OCR_Train.py", line 16, in <module>
    model.train(
  File "/home/jovyan/.conda/envs/aipbase2/lib/python3.10/site-packages/ultralytics/engine/model.py", line 802, in train
    self.trainer.train()
  File "/home/jovyan/.conda/envs/aipbase2/lib/python3.10/site-packages/ultralytics/engine/trainer.py", line 207, in train
    self._do_train(world_size)
  File "/home/jovyan/.conda/envs/aipbase2/lib/python3.10/site-packages/ultralytics/engine/trainer.py", line 385, in _do_train
    self.loss, self.loss_items = self.model(batch)
  File "/home/jovyan/.conda/envs/aipbase2/lib/python3.10/site-packages/torch/nn/modules/module.py", line 1736, in _wrapped_call_impl
    return self._call_impl(*args, **kwargs)
  File "/home/jovyan/.conda/envs/aipbase2/lib/python3.10/site-packages/torch/nn/modules/module.py", line 1747, in _call_impl
    return forward_call(*args, **kwargs)
  File "/home/jovyan/.conda/envs/aipbase2/lib/python3.10/site-packages/ultralytics/nn/tasks.py", line 111, in forward
    return self.loss(x, *args, **kwargs)
  File "/home/jovyan/.conda/envs/aipbase2/lib/python3.10/site-packages/ultralytics/nn/tasks.py", line 293, in loss
    return self.criterion(preds, batch)
  File "/home/jovyan/.conda/envs/aipbase2/lib/python3.10/site-packages/ultralytics/utils/loss.py", line 682, in __call__
    _, target_bboxes, target_scores, fg_mask, _ = self.assigner(
  File "/home/jovyan/.conda/envs/aipbase2/lib/python3.10/site-packages/torch/nn/modules/module.py", line 1736, in _wrapped_call_impl
    return self._call_impl(*args, **kwargs)
  File "/home/jovyan/.conda/envs/aipbase2/lib/python3.10/site-packages/torch/nn/modules/module.py", line 1747, in _call_impl
    return forward_call(*args, **kwargs)
  File "/home/jovyan/.conda/envs/aipbase2/lib/python3.10/site-packages/torch/utils/_contextlib.py", line 116, in decorate_context
    return func(*args, **kwargs)
  File "/home/jovyan/.conda/envs/aipbase2/lib/python3.10/site-packages/ultralytics/utils/tal.py", line 72, in forward
    mask_pos, align_metric, overlaps = self.get_pos_mask(
  File "/home/jovyan/.conda/envs/aipbase2/lib/python3.10/site-packages/ultralytics/utils/tal.py", line 94, in get_pos_mask
    align_metric, overlaps = self.get_box_metrics(pd_scores, pd_bboxes, gt_labels, gt_bboxes, mask_in_gts * mask_gt)
  File "/home/jovyan/.conda/envs/aipbase2/lib/python3.10/site-packages/ultralytics/utils/tal.py", line 113, in get_box_metrics
    bbox_scores[mask_gt] = pd_scores[ind[0], :, ind[1]][mask_gt]  # b, max_num_obj, h*w
RuntimeError: CUDA error: device-side assert triggered
CUDA kernel errors might be asynchronously reported at some other API call, so the stacktrace below might be incorrect.
For debugging consider passing CUDA_LAUNCH_BLOCKING=1
Compile with `TORCH_USE_CUDA_DSA` to enable device-side assertions.
