 FutureWarning: You are using `torch.load` with `weights_only=False` (the current default value), which uses the default pickle module implicitly. It is possible to construct malicious pickle data which will execute arbitrary code during unpickling (See https://github.com/pytorch/pytorch/blob/main/SECURITY.md#untrusted-models for more details). In a future release, the default value for `weights_only` will be flipped to `True`. This limits the functions that could be executed during unpickling. Arbitrary objects will no longer be allowed to be loaded via this mode unless they are explicitly allowlisted by the user via `torch.serialization.add_safe_globals`. We recommend you start setting `weights_only=True` for any use case where you don't have full control of the loaded file. Please open an issue on GitHub for any issues related to this experimental feature.
  state_dict = torch.load(model_path, map_location=device)
/home/jovyan/jonglae/Retry1/DO/OCR_Test.py:40: FutureWarning: You are using `torch.load` with `weights_only=False` (the current default value), which uses the default pickle module implicitly. It is possible to construct malicious pickle data which will execute arbitrary code during unpickling (See https://github.com/pytorch/pytorch/blob/main/SECURITY.md#untrusted-models for more details). In a future release, the default value for `weights_only` will be flipped to `True`. This limits the functions that could be executed during unpickling. Arbitrary objects will no longer be allowed to be loaded via this mode unless they are explicitly allowlisted by the user via `torch.serialization.add_safe_globals`. We recommend you start setting `weights_only=True` for any use case where you don't have full control of the loaded file. Please open an issue on GitHub for any issues related to this experimental feature.
  checkpoint = torch.load(model_path, map_location=device)
Traceback (most recent call last):
  File "/home/jovyan/jonglae/Retry1/DO/OCR_Test.py", line 124, in <module>
    process_folder(input_folder, output_folder)
  File "/home/jovyan/jonglae/Retry1/DO/OCR_Test.py", line 111, in process_folder
    processed_output = process_yolo_and_ocr(image, detector, recognizer, converter)
  File "/home/jovyan/jonglae/Retry1/DO/OCR_Test.py", line 79, in process_yolo_and_ocr
    ocr_result = get_text(
  File "/home/jovyan/STN/EasyOCR/easyocr/recognition.py", line 196, in get_text
    result1 = recognizer_predict(recognizer, converter, test_loader, batch_max_length,\
  File "/home/jovyan/STN/EasyOCR/easyocr/recognition.py", line 99, in recognizer_predict
    for image_tensors in test_loader:
  File "/home/jovyan/.conda/envs/aipbase/lib/python3.10/site-packages/torch/utils/data/dataloader.py", line 701, in __next__
    data = self._next_data()
  File "/home/jovyan/.conda/envs/aipbase/lib/python3.10/site-packages/torch/utils/data/dataloader.py", line 1465, in _next_data
    return self._process_data(data)
  File "/home/jovyan/.conda/envs/aipbase/lib/python3.10/site-packages/torch/utils/data/dataloader.py", line 1491, in _process_data
    data.reraise()
  File "/home/jovyan/.conda/envs/aipbase/lib/python3.10/site-packages/torch/_utils.py", line 715, in reraise
    raise exception
ValueError: Caught ValueError in DataLoader worker process 0.
Original Traceback (most recent call last):
  File "/home/jovyan/.conda/envs/aipbase/lib/python3.10/site-packages/torch/utils/data/_utils/worker.py", line 351, in _worker_loop
    data = fetcher.fetch(index)  # type: ignore[possibly-undefined]
  File "/home/jovyan/.conda/envs/aipbase/lib/python3.10/site-packages/torch/utils/data/_utils/fetch.py", line 52, in fetch
    data = [self.dataset[idx] for idx in possibly_batched_index]
  File "/home/jovyan/.conda/envs/aipbase/lib/python3.10/site-packages/torch/utils/data/_utils/fetch.py", line 52, in <listcomp>
    data = [self.dataset[idx] for idx in possibly_batched_index]
  File "/home/jovyan/STN/EasyOCR/easyocr/recognition.py", line 57, in __getitem__
    return Image.fromarray(img, 'L')
  File "/home/jovyan/.conda/envs/aipbase/lib/python3.10/site-packages/PIL/Image.py", line 2940, in fromarray
    raise ValueError(f"Too many dimensions: {ndim} > {ndmax}.")
ValueError: Too many dimensions: 3 > 2.
